CommandError: "192.168.0.2" is not a valid port number or address:port pair.
[24/Jun/2017 01:01:51] "GET / HTTP/1.1" 200 2304
Not Found: /favicon.ico
[24/Jun/2017 01:01:51] "GET /favicon.ico HTTP/1.1" 404 3648
Not Found: /apple-touch-icon-precomposed.png
[24/Jun/2017 01:01:51] "GET /apple-touch-icon-precomposed.png HTTP/1.1" 404 3711
Not Found: /apple-touch-icon.png
[24/Jun/2017 01:01:51] "GET /apple-touch-icon.png HTTP/1.1" 404 3675
[24/Jun/2017 01:01:59] "GET / HTTP/1.1" 200 2304
[24/Jun/2017 01:02:30] "GET / HTTP/1.1" 200 2304
[24/Jun/2017 01:02:32] "GET / HTTP/1.1" 200 2304
[24/Jun/2017 01:02:33] "GET /register/ HTTP/1.1" 200 2784
[24/Jun/2017 01:03:39] "GET /register/ HTTP/1.1" 200 2784
[24/Jun/2017 01:16:35] "GET /register/ HTTP/1.1" 200 2784
[24/Jun/2017 01:16:45] "GET / HTTP/1.1" 200 2304
Not Found: /favicon.ico
[24/Jun/2017 01:16:45] "GET /favicon.ico HTTP/1.1" 404 3654
[24/Jun/2017 01:16:47] "GET /login/ HTTP/1.1" 200 528
Not Found: /favicon.ico
[24/Jun/2017 01:16:47] "GET /favicon.ico HTTP/1.1" 404 3654
[24/Jun/2017 01:16:52] "POST /login/ HTTP/1.1" 200 528
[24/Jun/2017 01:16:54] "POST /login/ HTTP/1.1" 200 528
[24/Jun/2017 01:17:01] "POST /login/ HTTP/1.1" 200 528
[24/Jun/2017 01:17:14] "GET / HTTP/1.1" 200 2304
[24/Jun/2017 01:17:38] "GET / HTTP/1.1" 200 2304
Not Found: /favicon.ico
[24/Jun/2017 01:17:38] "GET /favicon.ico HTTP/1.1" 404 3654
[24/Jun/2017 01:17:40] "GET /login/ HTTP/1.1" 200 528
[24/Jun/2017 01:17:46] "POST /login/ HTTP/1.1" 200 528
[24/Jun/2017 01:17:48] "GET /find-id/ HTTP/1.1" 200 1981
[24/Jun/2017 01:19:39] "POST /find-id/ HTTP/1.1" 200 1981
[24/Jun/2017 01:21:56] "GET /find-id/ HTTP/1.1" 200 1981
[24/Jun/2017 01:21:59] "GET /login/ HTTP/1.1" 200 528
[24/Jun/2017 01:22:00] "GET / HTTP/1.1" 200 2304
Internal Server Error: /vocabulary/
Traceback (most recent call last):
  File "/usr/local/lib/python2.7/dist-packages/django/core/handlers/exception.py", line 41, in inner
    response = get_response(request)
  File "/usr/local/lib/python2.7/dist-packages/django/core/handlers/base.py", line 187, in _get_response
    response = self.process_exception_by_middleware(e, request)
  File "/usr/local/lib/python2.7/dist-packages/django/core/handlers/base.py", line 185, in _get_response
    response = wrapped_callback(request, *callback_args, **callback_kwargs)
  File "/home/knight/MyLang/mylang/views.py", line 369, in vocabulary
    with open('number.txt', 'rt') as f:
IOError: [Errno 2] No such file or directory: u'number.txt'
[24/Jun/2017 01:22:07] "GET /vocabulary/ HTTP/1.1" 500 63789
[24/Jun/2017 01:22:22] "GET /video/ HTTP/1.1" 200 12516
[24/Jun/2017 01:22:27] "GET /video/ HTTP/1.1" 200 12516
[24/Jun/2017 01:22:34] "GET /read/ HTTP/1.1" 200 397
[24/Jun/2017 01:23:12] "GET /login/ HTTP/1.1" 200 528
[24/Jun/2017 01:23:41] "POST /login/ HTTP/1.1" 200 528
[24/Jun/2017 01:24:02] "GET /login/ HTTP/1.1" 200 528
[24/Jun/2017 01:24:05] "GET /video/ HTTP/1.1" 200 12516
Internal Server Error: /vocabulary/
Traceback (most recent call last):
  File "/usr/local/lib/python2.7/dist-packages/django/core/handlers/exception.py", line 41, in inner
    response = get_response(request)
  File "/usr/local/lib/python2.7/dist-packages/django/core/handlers/base.py", line 187, in _get_response
    response = self.process_exception_by_middleware(e, request)
  File "/usr/local/lib/python2.7/dist-packages/django/core/handlers/base.py", line 185, in _get_response
    response = wrapped_callback(request, *callback_args, **callback_kwargs)
  File "/home/knight/MyLang/mylang/views.py", line 369, in vocabulary
    with open('number.txt', 'rt') as f:
IOError: [Errno 2] No such file or directory: u'number.txt'
[24/Jun/2017 01:24:13] "GET /vocabulary/ HTTP/1.1" 500 63789
[24/Jun/2017 01:28:58] "GET / HTTP/1.1" 200 2304
Not Found: /favicon.ico
[24/Jun/2017 01:28:58] "GET /favicon.ico HTTP/1.1" 404 3654
Internal Server Error: /vocabulary/
Traceback (most recent call last):
  File "/usr/local/lib/python2.7/dist-packages/django/core/handlers/exception.py", line 41, in inner
    response = get_response(request)
  File "/usr/local/lib/python2.7/dist-packages/django/core/handlers/base.py", line 187, in _get_response
    response = self.process_exception_by_middleware(e, request)
  File "/usr/local/lib/python2.7/dist-packages/django/core/handlers/base.py", line 185, in _get_response
    response = wrapped_callback(request, *callback_args, **callback_kwargs)
  File "/home/knight/MyLang/mylang/views.py", line 369, in vocabulary
    with open('number.txt', 'rt') as f:
IOError: [Errno 2] No such file or directory: u'number.txt'
[24/Jun/2017 01:29:00] "GET /vocabulary/ HTTP/1.1" 500 63789
[24/Jun/2017 01:31:35] code 400, message Bad request version ('MCTP/1.0')
[24/Jun/2017 01:31:35] "REMOTE HI_SRDK_DEV_GetHddInfo MCTP/1.0" 400 -
Performing system checks...

System check identified no issues (0 silenced).
June 24, 2017 - 01:01:49
Django version 1.11.1, using settings 'MyLang.settings'
Starting development server at http://192.168.0.2:8888/
Quit the server with CONTROL-C.
Internal Server Error: /vocabulary/
Traceback (most recent call last):
  File "/usr/local/lib/python2.7/dist-packages/django/core/handlers/exception.py", line 41, in inner
    response = get_response(request)
  File "/usr/local/lib/python2.7/dist-packages/django/core/handlers/base.py", line 187, in _get_response
    response = self.process_exception_by_middleware(e, request)
  File "/usr/local/lib/python2.7/dist-packages/django/core/handlers/base.py", line 185, in _get_response
    response = wrapped_callback(request, *callback_args, **callback_kwargs)
  File "/home/knight/MyLang/mylang/views.py", line 369, in vocabulary
    with open('./number.txt', 'rt') as f:
IOError: [Errno 2] No such file or directory: u'./number.txt'
[24/Jun/2017 01:35:41] "GET /vocabulary/ HTTP/1.1" 500 63934
Internal Server Error: /vocabulary/
Traceback (most recent call last):
  File "/usr/local/lib/python2.7/dist-packages/django/core/handlers/exception.py", line 41, in inner
    response = get_response(request)
  File "/usr/local/lib/python2.7/dist-packages/django/core/handlers/base.py", line 187, in _get_response
    response = self.process_exception_by_middleware(e, request)
  File "/usr/local/lib/python2.7/dist-packages/django/core/handlers/base.py", line 185, in _get_response
    response = wrapped_callback(request, *callback_args, **callback_kwargs)
  File "/home/knight/MyLang/mylang/views.py", line 369, in vocabulary
    with open('./number.txt', 'rt') as f:
IOError: [Errno 2] No such file or directory: u'./number.txt'
[24/Jun/2017 01:35:43] "GET /vocabulary/ HTTP/1.1" 500 63934
Performing system checks...

System check identified no issues (0 silenced).
June 24, 2017 - 01:35:28
Django version 1.11.1, using settings 'MyLang.settings'
Starting development server at http://192.168.0.2:8888/
Quit the server with CONTROL-C.
Internal Server Error: /vocabulary/
Traceback (most recent call last):
  File "/usr/local/lib/python2.7/dist-packages/django/core/handlers/exception.py", line 41, in inner
    response = get_response(request)
  File "/usr/local/lib/python2.7/dist-packages/django/core/handlers/base.py", line 187, in _get_response
    response = self.process_exception_by_middleware(e, request)
  File "/usr/local/lib/python2.7/dist-packages/django/core/handlers/base.py", line 185, in _get_response
    response = wrapped_callback(request, *callback_args, **callback_kwargs)
  File "/home/knight/MyLang/mylang/views.py", line 369, in vocabulary
    with open(str('./number.txt'), 'rt') as f:
IOError: [Errno 2] No such file or directory: './number.txt'
[24/Jun/2017 01:36:43] "GET /vocabulary/ HTTP/1.1" 500 63941
Performing system checks...

System check identified no issues (0 silenced).
June 24, 2017 - 01:36:41
Django version 1.11.1, using settings 'MyLang.settings'
Starting development server at http://192.168.0.2:8888/
Quit the server with CONTROL-C.
[24/Jun/2017 01:38:30] "GET /vocabulary/ HTTP/1.1" 200 112
[24/Jun/2017 01:38:48] "GET /vocabulary/ HTTP/1.1" 200 112
[24/Jun/2017 01:38:57] "GET /login/ HTTP/1.1" 200 528
[24/Jun/2017 01:39:05] "POST /login/ HTTP/1.1" 200 528
[24/Jun/2017 01:39:15] "POST /login/ HTTP/1.1" 200 528
[24/Jun/2017 01:39:22] "GET /admin HTTP/1.1" 301 0
[24/Jun/2017 01:39:22] "GET /admin/ HTTP/1.1" 302 0
[24/Jun/2017 01:39:22] "GET /admin/login/?next=/admin/ HTTP/1.1" 200 1650
[24/Jun/2017 01:39:22] "GET /static/admin/css/login.css HTTP/1.1" 200 1203
[24/Jun/2017 01:39:22] "GET /static/admin/css/base.css HTTP/1.1" 200 16066
[24/Jun/2017 01:39:22] "GET /static/admin/css/fonts.css HTTP/1.1" 200 423
[24/Jun/2017 01:39:22] "GET /static/admin/fonts/Roboto-Regular-webfont.woff HTTP/1.1" 200 80304
[24/Jun/2017 01:39:22] "GET /static/admin/fonts/Roboto-Light-webfont.woff HTTP/1.1" 200 81348
[24/Jun/2017 01:39:29] "POST /admin/login/?next=/admin/ HTTP/1.1" 302 0
[24/Jun/2017 01:39:29] "GET /admin/ HTTP/1.1" 200 7716
[24/Jun/2017 01:39:29] "GET /static/admin/css/dashboard.css HTTP/1.1" 200 412
[24/Jun/2017 01:39:29] "GET /static/admin/img/icon-deletelink.svg HTTP/1.1" 200 392
[24/Jun/2017 01:39:29] "GET /static/admin/img/icon-addlink.svg HTTP/1.1" 200 331
[24/Jun/2017 01:39:29] "GET /static/admin/fonts/Roboto-Bold-webfont.woff HTTP/1.1" 200 82564
[24/Jun/2017 01:39:29] "GET /static/admin/img/icon-changelink.svg HTTP/1.1" 200 380
[24/Jun/2017 01:39:31] "GET /admin/auth/user/ HTTP/1.1" 200 6465
[24/Jun/2017 01:39:31] "GET /static/admin/js/admin/RelatedObjectLookups.js HTTP/1.1" 200 6591
[24/Jun/2017 01:39:31] "GET /static/admin/js/core.js HTTP/1.1" 200 7976
[24/Jun/2017 01:39:31] "GET /static/admin/js/jquery.init.js HTTP/1.1" 200 363
[24/Jun/2017 01:39:31] "GET /static/admin/css/changelists.css HTTP/1.1" 200 6170
[24/Jun/2017 01:39:31] "GET /admin/jsi18n/ HTTP/1.1" 200 3217
[24/Jun/2017 01:39:31] "GET /static/admin/js/actions.js HTTP/1.1" 200 6501
[24/Jun/2017 01:39:31] "GET /static/admin/js/urlify.js HTTP/1.1" 200 8186
[24/Jun/2017 01:39:31] "GET /static/admin/js/prepopulate.js HTTP/1.1" 200 1538
[24/Jun/2017 01:39:31] "GET /static/admin/js/vendor/jquery/jquery.js HTTP/1.1" 200 258648
[24/Jun/2017 01:39:31] "GET /static/admin/js/vendor/xregexp/xregexp.js HTTP/1.1" 200 128820
[24/Jun/2017 01:39:31] "GET /static/admin/img/search.svg HTTP/1.1" 200 458
[24/Jun/2017 01:39:31] "GET /static/admin/img/icon-yes.svg HTTP/1.1" 200 436
[24/Jun/2017 01:39:31] "GET /static/admin/img/sorting-icons.svg HTTP/1.1" 200 1097
[24/Jun/2017 01:39:31] "GET /static/admin/img/tooltag-add.svg HTTP/1.1" 200 331
[24/Jun/2017 01:39:37] "GET /admin/ HTTP/1.1" 200 7716
Internal Server Error: /admin/mylang/user_info/
Traceback (most recent call last):
  File "/usr/local/lib/python2.7/dist-packages/django/core/handlers/exception.py", line 41, in inner
    response = get_response(request)
  File "/usr/local/lib/python2.7/dist-packages/django/core/handlers/base.py", line 187, in _get_response
    response = self.process_exception_by_middleware(e, request)
  File "/usr/local/lib/python2.7/dist-packages/django/core/handlers/base.py", line 185, in _get_response
    response = wrapped_callback(request, *callback_args, **callback_kwargs)
  File "/usr/local/lib/python2.7/dist-packages/django/contrib/admin/options.py", line 551, in wrapper
    return self.admin_site.admin_view(view)(*args, **kwargs)
  File "/usr/local/lib/python2.7/dist-packages/django/utils/decorators.py", line 149, in _wrapped_view
    response = view_func(request, *args, **kwargs)
  File "/usr/local/lib/python2.7/dist-packages/django/views/decorators/cache.py", line 57, in _wrapped_view_func
    response = view_func(request, *args, **kwargs)
  File "/usr/local/lib/python2.7/dist-packages/django/contrib/admin/sites.py", line 224, in inner
    return view(request, *args, **kwargs)
  File "/usr/local/lib/python2.7/dist-packages/django/utils/decorators.py", line 67, in _wrapper
    return bound_func(*args, **kwargs)
  File "/usr/local/lib/python2.7/dist-packages/django/utils/decorators.py", line 149, in _wrapped_view
    response = view_func(request, *args, **kwargs)
  File "/usr/local/lib/python2.7/dist-packages/django/utils/decorators.py", line 63, in bound_func
    return func.__get__(self, type(self))(*args2, **kwargs2)
  File "/usr/local/lib/python2.7/dist-packages/django/contrib/admin/options.py", line 1662, in changelist_view
    selection_note=_('0 of %(cnt)s selected') % {'cnt': len(cl.result_list)},
  File "/usr/local/lib/python2.7/dist-packages/django/db/models/query.py", line 232, in __len__
    self._fetch_all()
  File "/usr/local/lib/python2.7/dist-packages/django/db/models/query.py", line 1103, in _fetch_all
    self._result_cache = list(self._iterable_class(self))
  File "/usr/local/lib/python2.7/dist-packages/django/db/models/query.py", line 53, in __iter__
    results = compiler.execute_sql(chunked_fetch=self.chunked_fetch)
  File "/usr/local/lib/python2.7/dist-packages/django/db/models/sql/compiler.py", line 886, in execute_sql
    raise original_exception
OperationalError: no such column: mylang_user_info.total_level
[24/Jun/2017 01:39:38] "GET /admin/mylang/user_info/ HTTP/1.1" 500 117929
[24/Jun/2017 01:39:47] "GET /admin/ HTTP/1.1" 200 7716
[24/Jun/2017 01:39:53] "GET /admin/mylang/tmp_answer/ HTTP/1.1" 200 3069
[24/Jun/2017 01:39:53] "GET /admin/jsi18n/ HTTP/1.1" 200 3217
[24/Jun/2017 01:39:55] "GET /admin/ HTTP/1.1" 200 7716
[24/Jun/2017 01:39:56] "GET /admin/mylang/history/ HTTP/1.1" 200 4192
[24/Jun/2017 01:39:56] "GET /admin/jsi18n/ HTTP/1.1" 200 3217
[24/Jun/2017 01:39:58] "GET /admin/ HTTP/1.1" 200 7716
[24/Jun/2017 01:39:59] "GET /admin/mylang/voca/ HTTP/1.1" 200 27633
[24/Jun/2017 01:39:59] "GET /admin/jsi18n/ HTTP/1.1" 200 3217
[24/Jun/2017 01:40:05] "GET /admin/ HTTP/1.1" 200 7716
Internal Server Error: /admin/mylang/user_info/
Traceback (most recent call last):
  File "/usr/local/lib/python2.7/dist-packages/django/core/handlers/exception.py", line 41, in inner
    response = get_response(request)
  File "/usr/local/lib/python2.7/dist-packages/django/core/handlers/base.py", line 187, in _get_response
    response = self.process_exception_by_middleware(e, request)
  File "/usr/local/lib/python2.7/dist-packages/django/core/handlers/base.py", line 185, in _get_response
    response = wrapped_callback(request, *callback_args, **callback_kwargs)
  File "/usr/local/lib/python2.7/dist-packages/django/contrib/admin/options.py", line 551, in wrapper
    return self.admin_site.admin_view(view)(*args, **kwargs)
  File "/usr/local/lib/python2.7/dist-packages/django/utils/decorators.py", line 149, in _wrapped_view
    response = view_func(request, *args, **kwargs)
  File "/usr/local/lib/python2.7/dist-packages/django/views/decorators/cache.py", line 57, in _wrapped_view_func
    response = view_func(request, *args, **kwargs)
  File "/usr/local/lib/python2.7/dist-packages/django/contrib/admin/sites.py", line 224, in inner
    return view(request, *args, **kwargs)
  File "/usr/local/lib/python2.7/dist-packages/django/utils/decorators.py", line 67, in _wrapper
    return bound_func(*args, **kwargs)
  File "/usr/local/lib/python2.7/dist-packages/django/utils/decorators.py", line 149, in _wrapped_view
    response = view_func(request, *args, **kwargs)
  File "/usr/local/lib/python2.7/dist-packages/django/utils/decorators.py", line 63, in bound_func
    return func.__get__(self, type(self))(*args2, **kwargs2)
  File "/usr/local/lib/python2.7/dist-packages/django/contrib/admin/options.py", line 1662, in changelist_view
    selection_note=_('0 of %(cnt)s selected') % {'cnt': len(cl.result_list)},
  File "/usr/local/lib/python2.7/dist-packages/django/db/models/query.py", line 232, in __len__
    self._fetch_all()
  File "/usr/local/lib/python2.7/dist-packages/django/db/models/query.py", line 1103, in _fetch_all
    self._result_cache = list(self._iterable_class(self))
  File "/usr/local/lib/python2.7/dist-packages/django/db/models/query.py", line 53, in __iter__
    results = compiler.execute_sql(chunked_fetch=self.chunked_fetch)
  File "/usr/local/lib/python2.7/dist-packages/django/db/models/sql/compiler.py", line 886, in execute_sql
    raise original_exception
OperationalError: no such column: mylang_user_info.total_level
[24/Jun/2017 01:40:07] "GET /admin/mylang/user_info/ HTTP/1.1" 500 117929
[24/Jun/2017 01:42:22] "GET /login/ HTTP/1.1" 200 528
[24/Jun/2017 01:45:19] "GET /login/ HTTP/1.1" 200 528
[24/Jun/2017 01:45:21] "GET / HTTP/1.1" 200 2304
[24/Jun/2017 01:45:22] "GET /register/ HTTP/1.1" 200 2784
Internal Server Error: /register/
Traceback (most recent call last):
  File "/usr/local/lib/python2.7/dist-packages/django/core/handlers/exception.py", line 41, in inner
    response = get_response(request)
  File "/usr/local/lib/python2.7/dist-packages/django/core/handlers/base.py", line 187, in _get_response
    response = self.process_exception_by_middleware(e, request)
  File "/usr/local/lib/python2.7/dist-packages/django/core/handlers/base.py", line 185, in _get_response
    response = wrapped_callback(request, *callback_args, **callback_kwargs)
  File "/home/knight/MyLang/mylang/views.py", line 271, in register
    new_user.save()
  File "/usr/local/lib/python2.7/dist-packages/django/db/models/base.py", line 806, in save
    force_update=force_update, update_fields=update_fields)
  File "/usr/local/lib/python2.7/dist-packages/django/db/models/base.py", line 836, in save_base
    updated = self._save_table(raw, cls, force_insert, force_update, using, update_fields)
  File "/usr/local/lib/python2.7/dist-packages/django/db/models/base.py", line 922, in _save_table
    result = self._do_insert(cls._base_manager, using, fields, update_pk, raw)
  File "/usr/local/lib/python2.7/dist-packages/django/db/models/base.py", line 961, in _do_insert
    using=using, raw=raw)
  File "/usr/local/lib/python2.7/dist-packages/django/db/models/manager.py", line 85, in manager_method
    return getattr(self.get_queryset(), name)(*args, **kwargs)
  File "/usr/local/lib/python2.7/dist-packages/django/db/models/query.py", line 1061, in _insert
    return query.get_compiler(using=using).execute_sql(return_id)
  File "/usr/local/lib/python2.7/dist-packages/django/db/models/sql/compiler.py", line 1099, in execute_sql
    cursor.execute(sql, params)
  File "/usr/local/lib/python2.7/dist-packages/django/db/backends/utils.py", line 80, in execute
    return super(CursorDebugWrapper, self).execute(sql, params)
  File "/usr/local/lib/python2.7/dist-packages/django/db/backends/utils.py", line 65, in execute
    return self.cursor.execute(sql, params)
  File "/usr/local/lib/python2.7/dist-packages/django/db/utils.py", line 94, in __exit__
    six.reraise(dj_exc_type, dj_exc_value, traceback)
  File "/usr/local/lib/python2.7/dist-packages/django/db/backends/utils.py", line 65, in execute
    return self.cursor.execute(sql, params)
  File "/usr/local/lib/python2.7/dist-packages/django/db/backends/sqlite3/base.py", line 328, in execute
    return Database.Cursor.execute(self, query, params)
OperationalError: table mylang_user_info has no column named total_level
[24/Jun/2017 01:47:07] "POST /register/ HTTP/1.1" 500 126811
Performing system checks...

System check identified no issues (0 silenced).
June 24, 2017 - 01:38:27
Django version 1.11.1, using settings 'MyLang.settings'
Starting development server at http://192.168.0.2:8888/
Quit the server with CONTROL-C.
[24/Jun/2017 01:48:35] "GET /admin/ HTTP/1.1" 200 7716
[24/Jun/2017 01:48:36] "GET /admin/mylang/tmp_answer/ HTTP/1.1" 200 3069
[24/Jun/2017 01:48:36] "GET /admin/jsi18n/ HTTP/1.1" 200 3217
[24/Jun/2017 01:48:39] "GET /admin/ HTTP/1.1" 200 7716
[24/Jun/2017 01:48:40] "GET /admin/mylang/user_info/ HTTP/1.1" 200 4447
[24/Jun/2017 01:48:40] "GET /admin/jsi18n/ HTTP/1.1" 200 3217
[24/Jun/2017 01:48:41] "GET /admin/mylang/user_info/4/change/ HTTP/1.1" 200 7382
[24/Jun/2017 01:48:41] "GET /admin/jsi18n/ HTTP/1.1" 200 3217
[24/Jun/2017 01:48:41] "GET /static/admin/css/forms.css HTTP/1.1" 200 8173
[24/Jun/2017 01:48:41] "GET /static/admin/js/prepopulate_init.js HTTP/1.1" 200 495
[24/Jun/2017 01:48:41] "GET /static/admin/js/change_form.js HTTP/1.1" 200 712
[24/Jun/2017 01:48:42] "GET /static/admin/css/widgets.css HTTP/1.1" 200 10340
[24/Jun/2017 01:48:45] "GET /admin/mylang/user_info/ HTTP/1.1" 200 4447
[24/Jun/2017 01:48:45] "GET /admin/mylang/user_info/1/change/ HTTP/1.1" 200 7347
[24/Jun/2017 01:48:45] "GET /admin/jsi18n/ HTTP/1.1" 200 3217
[24/Jun/2017 01:49:36] "GET /login/ HTTP/1.1" 200 528
[24/Jun/2017 01:49:48] "POST /login/ HTTP/1.1" 302 0
[24/Jun/2017 01:49:48] "GET / HTTP/1.1" 200 2304
[24/Jun/2017 01:49:53] "GET /vocabulary/ HTTP/1.1" 200 5308
[24/Jun/2017 01:49:55] "GET / HTTP/1.1" 200 2304
[24/Jun/2017 01:50:11] "GET / HTTP/1.1" 200 2304
[24/Jun/2017 01:50:19] "GET /video/ HTTP/1.1" 200 12516
[24/Jun/2017 01:50:29] "GET /video/446cc4baea067a08a25cfef5b911d7afe4d68157785cb64857d44b26f89f08af HTTP/1.1" 301 0
[24/Jun/2017 01:50:30] "GET /video/446cc4baea067a08a25cfef5b911d7afe4d68157785cb64857d44b26f89f08af/ HTTP/1.1" 200 17184
[24/Jun/2017 01:50:47] "GET / HTTP/1.1" 200 8298
[24/Jun/2017 01:51:04] "GET /video/add/S7IepSMrD0E HTTP/1.1" 301 0
[24/Jun/2017 01:51:54] code 400, message Bad request version ('MCTP/1.0')
[24/Jun/2017 01:51:54] "REMOTE HI_SRDK_DEV_GetHddInfo MCTP/1.0" 400 -
[24/Jun/2017 01:55:03] "GET /video/ HTTP/1.1" 200 12516
[24/Jun/2017 01:55:05] "GET / HTTP/1.1" 200 8298
[24/Jun/2017 01:55:07] "GET /vocabulary/ HTTP/1.1" 200 5371
[24/Jun/2017 01:55:13] "GET / HTTP/1.1" 200 8298
Internal Server Error: /mypage/
Traceback (most recent call last):
  File "/usr/local/lib/python2.7/dist-packages/django/core/handlers/exception.py", line 41, in inner
    response = get_response(request)
  File "/usr/local/lib/python2.7/dist-packages/django/core/handlers/base.py", line 187, in _get_response
    response = self.process_exception_by_middleware(e, request)
  File "/usr/local/lib/python2.7/dist-packages/django/core/handlers/base.py", line 185, in _get_response
    response = wrapped_callback(request, *callback_args, **callback_kwargs)
  File "/home/knight/MyLang/mylang/views.py", line 333, in mypage
    ctx = {'level':pickle.loads(user.level)['en\r']}
AttributeError: 'user_info' object has no attribute 'level'
[24/Jun/2017 01:55:16] "GET /mypage/ HTTP/1.1" 500 65134
[24/Jun/2017 01:55:21] "GET / HTTP/1.1" 200 8298
[24/Jun/2017 01:55:24] "GET /video/ HTTP/1.1" 200 12516
[24/Jun/2017 01:55:34] "GET /video/ HTTP/1.1" 200 12516
[24/Jun/2017 01:55:37] "GET /video/dcb03ed340f21527ddac4f696883f48e6436154aab4c3d58d8c7b9cecf88a555 HTTP/1.1" 301 0
[24/Jun/2017 01:55:58] "GET /video/dcb03ed340f21527ddac4f696883f48e6436154aab4c3d58d8c7b9cecf88a555/ HTTP/1.1" 200 96001
[24/Jun/2017 01:56:06] "GET / HTTP/1.1" 200 7936
[24/Jun/2017 01:56:09] "GET /video/add/RdtHX15sXiU HTTP/1.1" 301 0
[24/Jun/2017 01:59:20] "GET /video/ HTTP/1.1" 200 12516
[24/Jun/2017 01:59:38] "GET /video/add HTTP/1.1" 301 0
[24/Jun/2017 01:59:38] "GET /video/add/ HTTP/1.1" 200 326
Forbidden (CSRF cookie not set.): /
[24/Jun/2017 02:33:09] "POST / HTTP/1.0" 403 2857
